2020-08-29 22:45:08,596 ERROR    D:\code\python_test\Gerber_blog\backend\blog_interface\user_views\views.py[line:37] {"email": [{"message": "Ensure this value has at most 20 characters (it has 24).", "code": "max_length"}]}
2020-08-29 22:45:08,649 ERROR    D:\code\python_test\Gerber_blog\blog_env\lib\site-packages\django\utils\log.py[line:228] Internal Server Error: /api/user/register
Traceback (most recent call last):
  File "D:\code\python_test\Gerber_blog\blog_env\lib\site-packages\django\core\handlers\exception.py", line 34, in inner
    response = get_response(request)
  File "D:\code\python_test\Gerber_blog\blog_env\lib\site-packages\django\core\handlers\base.py", line 115, in _get_response
    response = self.process_exception_by_middleware(e, request)
  File "D:\code\python_test\Gerber_blog\blog_env\lib\site-packages\django\core\handlers\base.py", line 113, in _get_response
    response = wrapped_callback(request, *callback_args, **callback_kwargs)
  File "D:\code\python_test\Gerber_blog\blog_env\lib\site-packages\django\views\generic\base.py", line 71, in view
    return self.dispatch(request, *args, **kwargs)
  File "D:\code\python_test\Gerber_blog\blog_env\lib\site-packages\django\views\generic\base.py", line 97, in dispatch
    return handler(request, *args, **kwargs)
  File "D:\code\python_test\Gerber_blog\backend\blog_interface\user_views\views.py", line 38, in post
    raise MyException()
blog_interface.Exception.my_exception.MyException: ²ÎÊý´íÎó
2020-08-29 22:45:08,650 ERROR    D:\code\python_test\Gerber_blog\blog_env\lib\site-packages\django\core\servers\basehttp.py[line:154] "POST /api/user/register HTTP/1.0" 500 80162
2020-08-29 22:45:58,272 INFO     D:\code\python_test\Gerber_blog\blog_env\lib\site-packages\django\utils\autoreload.py[line:217] D:\code\python_test\Gerber_blog\backend\blog_interface\Form\user.py changed, reloading.
2020-08-29 22:45:59,172 INFO     D:\code\python_test\Gerber_blog\blog_env\lib\site-packages\django\utils\autoreload.py[line:597] Watching for file changes with StatReloader
2020-08-29 22:46:04,021 INFO     D:\code\python_test\Gerber_blog\blog_env\lib\site-packages\django\core\servers\basehttp.py[line:154] "POST /api/user/register HTTP/1.0" 200 44
2020-08-29 23:11:04,535 ERROR    D:\code\python_test\Gerber_blog\blog_env\lib\site-packages\django\utils\log.py[line:228] Internal Server Error: /api/user/register
Traceback (most recent call last):
  File "D:\code\python_test\Gerber_blog\blog_env\lib\site-packages\django\db\backends\utils.py", line 84, in _execute
    return self.cursor.execute(sql, params)
  File "D:\code\python_test\Gerber_blog\blog_env\lib\site-packages\django\db\backends\sqlite3\base.py", line 383, in execute
    return Database.Cursor.execute(self, query, params)
sqlite3.IntegrityError: UNIQUE constraint failed: auth_user.username

The above exception was the direct cause of the following exception:

Traceback (most recent call last):
  File "D:\code\python_test\Gerber_blog\blog_env\lib\site-packages\django\core\handlers\exception.py", line 34, in inner
    response = get_response(request)
  File "D:\code\python_test\Gerber_blog\blog_env\lib\site-packages\django\core\handlers\base.py", line 115, in _get_response
    response = self.process_exception_by_middleware(e, request)
  File "D:\code\python_test\Gerber_blog\blog_env\lib\site-packages\django\core\handlers\base.py", line 113, in _get_response
    response = wrapped_callback(request, *callback_args, **callback_kwargs)
  File "D:\code\python_test\Gerber_blog\blog_env\lib\site-packages\django\views\generic\base.py", line 71, in view
    return self.dispatch(request, *args, **kwargs)
  File "D:\code\python_test\Gerber_blog\blog_env\lib\site-packages\django\views\generic\base.py", line 97, in dispatch
    return handler(request, *args, **kwargs)
  File "D:\code\python_test\Gerber_blog\backend\blog_interface\user_views\views.py", line 29, in post
    email=form.cleaned_data['email'])
  File "D:\code\python_test\Gerber_blog\blog_env\lib\site-packages\django\contrib\auth\models.py", line 151, in create_user
    return self._create_user(username, email, password, **extra_fields)
  File "D:\code\python_test\Gerber_blog\blog_env\lib\site-packages\django\contrib\auth\models.py", line 145, in _create_user
    user.save(using=self._db)
  File "D:\code\python_test\Gerber_blog\blog_env\lib\site-packages\django\contrib\auth\base_user.py", line 66, in save
    super().save(*args, **kwargs)
  File "D:\code\python_test\Gerber_blog\blog_env\lib\site-packages\django\db\models\base.py", line 741, in save
    force_update=force_update, update_fields=update_fields)
  File "D:\code\python_test\Gerber_blog\blog_env\lib\site-packages\django\db\models\base.py", line 779, in save_base
    force_update, using, update_fields,
  File "D:\code\python_test\Gerber_blog\blog_env\lib\site-packages\django\db\models\base.py", line 870, in _save_table
    result = self._do_insert(cls._base_manager, using, fields, update_pk, raw)
  File "D:\code\python_test\Gerber_blog\blog_env\lib\site-packages\django\db\models\base.py", line 908, in _do_insert
    using=using, raw=raw)
  File "D:\code\python_test\Gerber_blog\blog_env\lib\site-packages\django\db\models\manager.py", line 82, in manager_method
    return getattr(self.get_queryset(), name)(*args, **kwargs)
  File "D:\code\python_test\Gerber_blog\blog_env\lib\site-packages\django\db\models\query.py", line 1186, in _insert
    return query.get_compiler(using=using).execute_sql(return_id)
  File "D:\code\python_test\Gerber_blog\blog_env\lib\site-packages\django\db\models\sql\compiler.py", line 1375, in execute_sql
    cursor.execute(sql, params)
  File "D:\code\python_test\Gerber_blog\blog_env\lib\site-packages\django\db\backends\utils.py", line 99, in execute
    return super().execute(sql, params)
  File "D:\code\python_test\Gerber_blog\blog_env\lib\site-packages\django\db\backends\utils.py", line 67, in execute
    return self._execute_with_wrappers(sql, params, many=False, executor=self._execute)
  File "D:\code\python_test\Gerber_blog\blog_env\lib\site-packages\django\db\backends\utils.py", line 76, in _execute_with_wrappers
    return executor(sql, params, many, context)
  File "D:\code\python_test\Gerber_blog\blog_env\lib\site-packages\django\db\backends\utils.py", line 84, in _execute
    return self.cursor.execute(sql, params)
  File "D:\code\python_test\Gerber_blog\blog_env\lib\site-packages\django\db\utils.py", line 89, in __exit__
    raise dj_exc_value.with_traceback(traceback) from exc_value
  File "D:\code\python_test\Gerber_blog\blog_env\lib\site-packages\django\db\backends\utils.py", line 84, in _execute
    return self.cursor.execute(sql, params)
  File "D:\code\python_test\Gerber_blog\blog_env\lib\site-packages\django\db\backends\sqlite3\base.py", line 383, in execute
    return Database.Cursor.execute(self, query, params)
django.db.utils.IntegrityError: UNIQUE constraint failed: auth_user.username
2020-08-29 23:11:04,546 ERROR    D:\code\python_test\Gerber_blog\blog_env\lib\site-packages\django\core\servers\basehttp.py[line:154] "POST /api/user/register HTTP/1.0" 500 179403
2020-08-29 23:12:59,502 ERROR    D:\code\python_test\Gerber_blog\blog_env\lib\site-packages\django\utils\log.py[line:228] Internal Server Error: /api/user/register
Traceback (most recent call last):
  File "D:\code\python_test\Gerber_blog\blog_env\lib\site-packages\django\db\backends\utils.py", line 84, in _execute
    return self.cursor.execute(sql, params)
  File "D:\code\python_test\Gerber_blog\blog_env\lib\site-packages\django\db\backends\sqlite3\base.py", line 383, in execute
    return Database.Cursor.execute(self, query, params)
sqlite3.IntegrityError: UNIQUE constraint failed: auth_user.username

The above exception was the direct cause of the following exception:

Traceback (most recent call last):
  File "D:\code\python_test\Gerber_blog\blog_env\lib\site-packages\django\core\handlers\exception.py", line 34, in inner
    response = get_response(request)
  File "D:\code\python_test\Gerber_blog\blog_env\lib\site-packages\django\core\handlers\base.py", line 115, in _get_response
    response = self.process_exception_by_middleware(e, request)
  File "D:\code\python_test\Gerber_blog\blog_env\lib\site-packages\django\core\handlers\base.py", line 113, in _get_response
    response = wrapped_callback(request, *callback_args, **callback_kwargs)
  File "D:\code\python_test\Gerber_blog\blog_env\lib\site-packages\django\views\generic\base.py", line 71, in view
    return self.dispatch(request, *args, **kwargs)
  File "D:\code\python_test\Gerber_blog\blog_env\lib\site-packages\django\views\generic\base.py", line 97, in dispatch
    return handler(request, *args, **kwargs)
  File "D:\code\python_test\Gerber_blog\backend\blog_interface\user_views\views.py", line 29, in post
    email=form.cleaned_data['email'])
  File "D:\code\python_test\Gerber_blog\blog_env\lib\site-packages\django\contrib\auth\models.py", line 151, in create_user
    return self._create_user(username, email, password, **extra_fields)
  File "D:\code\python_test\Gerber_blog\blog_env\lib\site-packages\django\contrib\auth\models.py", line 145, in _create_user
    user.save(using=self._db)
  File "D:\code\python_test\Gerber_blog\blog_env\lib\site-packages\django\contrib\auth\base_user.py", line 66, in save
    super().save(*args, **kwargs)
  File "D:\code\python_test\Gerber_blog\blog_env\lib\site-packages\django\db\models\base.py", line 741, in save
    force_update=force_update, update_fields=update_fields)
  File "D:\code\python_test\Gerber_blog\blog_env\lib\site-packages\django\db\models\base.py", line 779, in save_base
    force_update, using, update_fields,
  File "D:\code\python_test\Gerber_blog\blog_env\lib\site-packages\django\db\models\base.py", line 870, in _save_table
    result = self._do_insert(cls._base_manager, using, fields, update_pk, raw)
  File "D:\code\python_test\Gerber_blog\blog_env\lib\site-packages\django\db\models\base.py", line 908, in _do_insert
    using=using, raw=raw)
  File "D:\code\python_test\Gerber_blog\blog_env\lib\site-packages\django\db\models\manager.py", line 82, in manager_method
    return getattr(self.get_queryset(), name)(*args, **kwargs)
  File "D:\code\python_test\Gerber_blog\blog_env\lib\site-packages\django\db\models\query.py", line 1186, in _insert
    return query.get_compiler(using=using).execute_sql(return_id)
  File "D:\code\python_test\Gerber_blog\blog_env\lib\site-packages\django\db\models\sql\compiler.py", line 1375, in execute_sql
    cursor.execute(sql, params)
  File "D:\code\python_test\Gerber_blog\blog_env\lib\site-packages\django\db\backends\utils.py", line 99, in execute
    return super().execute(sql, params)
  File "D:\code\python_test\Gerber_blog\blog_env\lib\site-packages\django\db\backends\utils.py", line 67, in execute
    return self._execute_with_wrappers(sql, params, many=False, executor=self._execute)
  File "D:\code\python_test\Gerber_blog\blog_env\lib\site-packages\django\db\backends\utils.py", line 76, in _execute_with_wrappers
    return executor(sql, params, many, context)
  File "D:\code\python_test\Gerber_blog\blog_env\lib\site-packages\django\db\backends\utils.py", line 84, in _execute
    return self.cursor.execute(sql, params)
  File "D:\code\python_test\Gerber_blog\blog_env\lib\site-packages\django\db\utils.py", line 89, in __exit__
    raise dj_exc_value.with_traceback(traceback) from exc_value
  File "D:\code\python_test\Gerber_blog\blog_env\lib\site-packages\django\db\backends\utils.py", line 84, in _execute
    return self.cursor.execute(sql, params)
  File "D:\code\python_test\Gerber_blog\blog_env\lib\site-packages\django\db\backends\sqlite3\base.py", line 383, in execute
    return Database.Cursor.execute(self, query, params)
django.db.utils.IntegrityError: UNIQUE constraint failed: auth_user.username
2020-08-29 23:12:59,506 ERROR    D:\code\python_test\Gerber_blog\blog_env\lib\site-packages\django\core\servers\basehttp.py[line:154] "POST /api/user/register HTTP/1.0" 500 179404
2020-08-29 23:28:16,298 WARNING  D:\code\python_test\Gerber_blog\blog_env\lib\site-packages\django\utils\log.py[line:228] Not Found: /api/api/user/register/
2020-08-29 23:28:16,298 WARNING  D:\code\python_test\Gerber_blog\blog_env\lib\site-packages\django\core\servers\basehttp.py[line:154] "POST /api/api/user/register/ HTTP/1.0" 404 2129
2020-08-29 23:29:54,306 WARNING  D:\code\python_test\Gerber_blog\blog_env\lib\site-packages\django\utils\log.py[line:228] Not Found: /api/user/register/
2020-08-29 23:29:54,306 WARNING  D:\code\python_test\Gerber_blog\blog_env\lib\site-packages\django\core\servers\basehttp.py[line:154] "POST /api/user/register/ HTTP/1.0" 404 2117
2020-08-29 23:31:24,597 WARNING  D:\code\python_test\Gerber_blog\blog_env\lib\site-packages\django\utils\log.py[line:228] Not Found: /api/user/register/
2020-08-29 23:31:24,598 WARNING  D:\code\python_test\Gerber_blog\blog_env\lib\site-packages\django\core\servers\basehttp.py[line:154] "POST /api/user/register/ HTTP/1.0" 404 2117
2020-08-29 23:31:33,814 ERROR    D:\code\python_test\Gerber_blog\blog_env\lib\site-packages\django\utils\log.py[line:228] Internal Server Error: /api/user/register
Traceback (most recent call last):
  File "D:\code\python_test\Gerber_blog\blog_env\lib\site-packages\django\db\backends\utils.py", line 84, in _execute
    return self.cursor.execute(sql, params)
  File "D:\code\python_test\Gerber_blog\blog_env\lib\site-packages\django\db\backends\sqlite3\base.py", line 383, in execute
    return Database.Cursor.execute(self, query, params)
sqlite3.IntegrityError: UNIQUE constraint failed: auth_user.username

The above exception was the direct cause of the following exception:

Traceback (most recent call last):
  File "D:\code\python_test\Gerber_blog\blog_env\lib\site-packages\django\core\handlers\exception.py", line 34, in inner
    response = get_response(request)
  File "D:\code\python_test\Gerber_blog\blog_env\lib\site-packages\django\core\handlers\base.py", line 115, in _get_response
    response = self.process_exception_by_middleware(e, request)
  File "D:\code\python_test\Gerber_blog\blog_env\lib\site-packages\django\core\handlers\base.py", line 113, in _get_response
    response = wrapped_callback(request, *callback_args, **callback_kwargs)
  File "D:\code\python_test\Gerber_blog\blog_env\lib\site-packages\django\views\generic\base.py", line 71, in view
    return self.dispatch(request, *args, **kwargs)
  File "D:\code\python_test\Gerber_blog\blog_env\lib\site-packages\django\views\generic\base.py", line 97, in dispatch
    return handler(request, *args, **kwargs)
  File "D:\code\python_test\Gerber_blog\backend\blog_interface\user_views\views.py", line 29, in post
    email=form.cleaned_data['email'])
  File "D:\code\python_test\Gerber_blog\blog_env\lib\site-packages\django\contrib\auth\models.py", line 151, in create_user
    return self._create_user(username, email, password, **extra_fields)
  File "D:\code\python_test\Gerber_blog\blog_env\lib\site-packages\django\contrib\auth\models.py", line 145, in _create_user
    user.save(using=self._db)
  File "D:\code\python_test\Gerber_blog\blog_env\lib\site-packages\django\contrib\auth\base_user.py", line 66, in save
    super().save(*args, **kwargs)
  File "D:\code\python_test\Gerber_blog\blog_env\lib\site-packages\django\db\models\base.py", line 741, in save
    force_update=force_update, update_fields=update_fields)
  File "D:\code\python_test\Gerber_blog\blog_env\lib\site-packages\django\db\models\base.py", line 779, in save_base
    force_update, using, update_fields,
  File "D:\code\python_test\Gerber_blog\blog_env\lib\site-packages\django\db\models\base.py", line 870, in _save_table
    result = self._do_insert(cls._base_manager, using, fields, update_pk, raw)
  File "D:\code\python_test\Gerber_blog\blog_env\lib\site-packages\django\db\models\base.py", line 908, in _do_insert
    using=using, raw=raw)
  File "D:\code\python_test\Gerber_blog\blog_env\lib\site-packages\django\db\models\manager.py", line 82, in manager_method
    return getattr(self.get_queryset(), name)(*args, **kwargs)
  File "D:\code\python_test\Gerber_blog\blog_env\lib\site-packages\django\db\models\query.py", line 1186, in _insert
    return query.get_compiler(using=using).execute_sql(return_id)
  File "D:\code\python_test\Gerber_blog\blog_env\lib\site-packages\django\db\models\sql\compiler.py", line 1375, in execute_sql
    cursor.execute(sql, params)
  File "D:\code\python_test\Gerber_blog\blog_env\lib\site-packages\django\db\backends\utils.py", line 99, in execute
    return super().execute(sql, params)
  File "D:\code\python_test\Gerber_blog\blog_env\lib\site-packages\django\db\backends\utils.py", line 67, in execute
    return self._execute_with_wrappers(sql, params, many=False, executor=self._execute)
  File "D:\code\python_test\Gerber_blog\blog_env\lib\site-packages\django\db\backends\utils.py", line 76, in _execute_with_wrappers
    return executor(sql, params, many, context)
  File "D:\code\python_test\Gerber_blog\blog_env\lib\site-packages\django\db\backends\utils.py", line 84, in _execute
    return self.cursor.execute(sql, params)
  File "D:\code\python_test\Gerber_blog\blog_env\lib\site-packages\django\db\utils.py", line 89, in __exit__
    raise dj_exc_value.with_traceback(traceback) from exc_value
  File "D:\code\python_test\Gerber_blog\blog_env\lib\site-packages\django\db\backends\utils.py", line 84, in _execute
    return self.cursor.execute(sql, params)
  File "D:\code\python_test\Gerber_blog\blog_env\lib\site-packages\django\db\backends\sqlite3\base.py", line 383, in execute
    return Database.Cursor.execute(self, query, params)
django.db.utils.IntegrityError: UNIQUE constraint failed: auth_user.username
2020-08-29 23:31:33,815 ERROR    D:\code\python_test\Gerber_blog\blog_env\lib\site-packages\django\core\servers\basehttp.py[line:154] "POST /api/user/register HTTP/1.0" 500 179404
2020-08-29 23:31:47,569 INFO     D:\code\python_test\Gerber_blog\blog_env\lib\site-packages\django\utils\autoreload.py[line:217] D:\code\python_test\Gerber_blog\backend\gerber_blog\urls.py changed, reloading.
2020-08-29 23:31:48,441 INFO     D:\code\python_test\Gerber_blog\blog_env\lib\site-packages\django\utils\autoreload.py[line:597] Watching for file changes with StatReloader
2020-08-29 23:32:08,136 INFO     D:\code\python_test\Gerber_blog\blog_env\lib\site-packages\django\core\servers\basehttp.py[line:154] "POST /api/user/register/ HTTP/1.0" 200 44
2020-08-29 23:35:00,094 INFO     D:\code\python_test\Gerber_blog\blog_env\lib\site-packages\django\core\servers\basehttp.py[line:154] "POST /api/user/register/ HTTP/1.0" 200 44
2020-08-29 23:36:38,947 INFO     D:\code\python_test\Gerber_blog\blog_env\lib\site-packages\django\core\servers\basehttp.py[line:154] "POST /api/user/register/ HTTP/1.0" 200 44
2020-08-30 20:42:07,995 INFO     D:\code\python_test\Gerber_blog\blog_env\lib\site-packages\django\utils\autoreload.py[line:597] Watching for file changes with StatReloader
2020-08-30 20:44:50,891 WARNING  D:\code\python_test\Gerber_blog\blog_env\lib\site-packages\django\utils\log.py[line:228] Not Found: /api/outh/AboutMeData
2020-08-30 20:44:50,892 WARNING  D:\code\python_test\Gerber_blog\blog_env\lib\site-packages\django\utils\log.py[line:228] Not Found: /api/article/ArtClassData
2020-08-30 20:44:50,893 WARNING  D:\code\python_test\Gerber_blog\blog_env\lib\site-packages\django\utils\log.py[line:228] Not Found: /api/nav/ActiveClassAllData
2020-08-30 20:44:50,894 WARNING  D:\code\python_test\Gerber_blog\blog_env\lib\site-packages\django\utils\log.py[line:228] Not Found: /api/article/ShowBrowseCount
2020-08-30 20:44:50,895 WARNING  D:\code\python_test\Gerber_blog\blog_env\lib\site-packages\django\core\servers\basehttp.py[line:154] "GET /api/article/ArtClassData HTTP/1.0" 404 2135
2020-08-30 20:44:50,895 WARNING  D:\code\python_test\Gerber_blog\blog_env\lib\site-packages\django\core\servers\basehttp.py[line:154] "GET /api/outh/AboutMeData HTTP/1.0" 404 2123
2020-08-30 20:44:50,895 WARNING  D:\code\python_test\Gerber_blog\blog_env\lib\site-packages\django\core\servers\basehttp.py[line:154] "GET /api/nav/ActiveClassAllData?art_id=0&cate_id=0&article_name= HTTP/1.0" 404 2182
2020-08-30 20:44:50,897 WARNING  D:\code\python_test\Gerber_blog\blog_env\lib\site-packages\django\utils\log.py[line:228] Not Found: /api/outh/ThemeMy
2020-08-30 20:44:50,897 WARNING  D:\code\python_test\Gerber_blog\blog_env\lib\site-packages\django\core\servers\basehttp.py[line:154] "GET /api/article/ShowBrowseCount HTTP/1.0" 404 2144
2020-08-30 20:44:50,898 WARNING  D:\code\python_test\Gerber_blog\blog_env\lib\site-packages\django\core\servers\basehttp.py[line:154] "GET /api/outh/ThemeMy HTTP/1.0" 404 2111
2020-08-30 20:44:50,929 WARNING  D:\code\python_test\Gerber_blog\blog_env\lib\site-packages\django\utils\log.py[line:228] Not Found: /api/article/ShowArtCommentCount
2020-08-30 20:44:50,931 WARNING  D:\code\python_test\Gerber_blog\blog_env\lib\site-packages\django\utils\log.py[line:228] Not Found: /api/outh/showLikeData
2020-08-30 20:44:50,933 WARNING  D:\code\python_test\Gerber_blog\blog_env\lib\site-packages\django\utils\log.py[line:228] Not Found: /api/article/ArtClassData
2020-08-30 20:44:50,934 WARNING  D:\code\python_test\Gerber_blog\blog_env\lib\site-packages\django\core\servers\basehttp.py[line:154] "GET /api/article/ShowArtCommentCount HTTP/1.0" 404 2156
2020-08-30 20:44:50,934 WARNING  D:\code\python_test\Gerber_blog\blog_env\lib\site-packages\django\core\servers\basehttp.py[line:154] "GET /api/outh/showLikeData HTTP/1.0" 404 2126
2020-08-30 20:44:50,936 WARNING  D:\code\python_test\Gerber_blog\blog_env\lib\site-packages\django\core\servers\basehttp.py[line:154] "GET /api/article/ArtClassData HTTP/1.0" 404 2135
2020-08-30 20:44:51,357 WARNING  D:\code\python_test\Gerber_blog\blog_env\lib\site-packages\django\utils\log.py[line:228] Not Found: /api/nav/navMenList
2020-08-30 20:44:51,358 WARNING  D:\code\python_test\Gerber_blog\blog_env\lib\site-packages\django\core\servers\basehttp.py[line:154] "GET /api/nav/navMenList HTTP/1.0" 404 2117
2020-08-30 20:45:40,035 ERROR    D:\code\python_test\Gerber_blog\backend\blog_interface\user_views\views.py[line:37] {"username": [{"message": "Ensure this value has at least 3 characters (it has 2).", "code": "min_length"}]}
2020-08-30 20:45:40,196 ERROR    D:\code\python_test\Gerber_blog\blog_env\lib\site-packages\django\utils\log.py[line:228] Internal Server Error: /api/user/register/
Traceback (most recent call last):
  File "D:\code\python_test\Gerber_blog\blog_env\lib\site-packages\django\core\handlers\exception.py", line 34, in inner
    response = get_response(request)
  File "D:\code\python_test\Gerber_blog\blog_env\lib\site-packages\django\core\handlers\base.py", line 115, in _get_response
    response = self.process_exception_by_middleware(e, request)
  File "D:\code\python_test\Gerber_blog\blog_env\lib\site-packages\django\core\handlers\base.py", line 113, in _get_response
    response = wrapped_callback(request, *callback_args, **callback_kwargs)
  File "D:\code\python_test\Gerber_blog\blog_env\lib\site-packages\django\views\generic\base.py", line 71, in view
    return self.dispatch(request, *args, **kwargs)
  File "D:\code\python_test\Gerber_blog\blog_env\lib\site-packages\django\views\generic\base.py", line 97, in dispatch
    return handler(request, *args, **kwargs)
  File "D:\code\python_test\Gerber_blog\backend\blog_interface\user_views\views.py", line 38, in post
    raise MyException()
blog_interface.Exception.my_exception.MyException: ²ÎÊý´íÎó
2020-08-30 20:45:40,203 ERROR    D:\code\python_test\Gerber_blog\blog_env\lib\site-packages\django\core\servers\basehttp.py[line:154] "POST /api/user/register/ HTTP/1.0" 500 80835
2020-08-30 20:46:45,086 WARNING  D:\code\python_test\Gerber_blog\blog_env\lib\site-packages\django\utils\log.py[line:228] Not Found: /api/article/ArtClassData
2020-08-30 20:46:45,088 WARNING  D:\code\python_test\Gerber_blog\blog_env\lib\site-packages\django\core\servers\basehttp.py[line:154] "GET /api/article/ArtClassData HTTP/1.0" 404 2135
2020-08-30 20:46:45,090 WARNING  D:\code\python_test\Gerber_blog\blog_env\lib\site-packages\django\utils\log.py[line:228] Not Found: /api/nav/navMenList
2020-08-30 20:46:45,091 WARNING  D:\code\python_test\Gerber_blog\blog_env\lib\site-packages\django\utils\log.py[line:228] Not Found: /api/outh/ThemeMy
2020-08-30 20:46:45,092 WARNING  D:\code\python_test\Gerber_blog\blog_env\lib\site-packages\django\core\servers\basehttp.py[line:154] "GET /api/nav/navMenList HTTP/1.0" 404 2117
2020-08-30 20:46:45,094 WARNING  D:\code\python_test\Gerber_blog\blog_env\lib\site-packages\django\utils\log.py[line:228] Not Found: /api/nav/ActiveClassAllData
2020-08-30 20:46:45,099 WARNING  D:\code\python_test\Gerber_blog\blog_env\lib\site-packages\django\utils\log.py[line:228] Not Found: /api/outh/AboutMeData
2020-08-30 20:46:45,102 WARNING  D:\code\python_test\Gerber_blog\blog_env\lib\site-packages\django\core\servers\basehttp.py[line:154] "GET /api/outh/AboutMeData HTTP/1.0" 404 2123
2020-08-30 20:46:45,102 WARNING  D:\code\python_test\Gerber_blog\blog_env\lib\site-packages\django\core\servers\basehttp.py[line:154] "GET /api/outh/ThemeMy HTTP/1.0" 404 2111
2020-08-30 20:46:45,104 WARNING  D:\code\python_test\Gerber_blog\blog_env\lib\site-packages\django\core\servers\basehttp.py[line:154] "GET /api/nav/ActiveClassAllData?art_id=0&cate_id=0&article_name= HTTP/1.0" 404 2182
2020-08-30 20:46:45,106 WARNING  D:\code\python_test\Gerber_blog\blog_env\lib\site-packages\django\utils\log.py[line:228] Not Found: /api/article/ShowBrowseCount
2020-08-30 20:46:45,111 WARNING  D:\code\python_test\Gerber_blog\blog_env\lib\site-packages\django\core\servers\basehttp.py[line:154] "GET /api/article/ShowBrowseCount HTTP/1.0" 404 2144
2020-08-30 20:46:45,118 WARNING  D:\code\python_test\Gerber_blog\blog_env\lib\site-packages\django\utils\log.py[line:228] Not Found: /api/article/ShowArtCommentCount
2020-08-30 20:46:45,119 WARNING  D:\code\python_test\Gerber_blog\blog_env\lib\site-packages\django\core\servers\basehttp.py[line:154] "GET /api/article/ShowArtCommentCount HTTP/1.0" 404 2156
2020-08-30 20:46:45,128 WARNING  D:\code\python_test\Gerber_blog\blog_env\lib\site-packages\django\utils\log.py[line:228] Not Found: /api/outh/showLikeData
2020-08-30 20:46:45,129 WARNING  D:\code\python_test\Gerber_blog\blog_env\lib\site-packages\django\core\servers\basehttp.py[line:154] "GET /api/outh/showLikeData HTTP/1.0" 404 2126
2020-08-30 20:46:45,139 WARNING  D:\code\python_test\Gerber_blog\blog_env\lib\site-packages\django\utils\log.py[line:228] Not Found: /api/article/ArtClassData
2020-08-30 20:46:45,140 WARNING  D:\code\python_test\Gerber_blog\blog_env\lib\site-packages\django\core\servers\basehttp.py[line:154] "GET /api/article/ArtClassData HTTP/1.0" 404 2135
2020-08-30 20:47:13,635 INFO     D:\code\python_test\Gerber_blog\blog_env\lib\site-packages\django\core\servers\basehttp.py[line:154] "POST /api/user/register/ HTTP/1.0" 200 44
2020-08-30 20:55:08,706 WARNING  D:\code\python_test\Gerber_blog\blog_env\lib\site-packages\django\utils\log.py[line:228] Not Found: /api/admin
2020-08-30 20:55:08,707 WARNING  D:\code\python_test\Gerber_blog\blog_env\lib\site-packages\django\core\servers\basehttp.py[line:154] "GET /api/admin HTTP/1.0" 404 2090
2020-08-30 20:55:11,095 WARNING  D:\code\python_test\Gerber_blog\blog_env\lib\site-packages\django\utils\log.py[line:228] Not Found: /api/admin/
2020-08-30 20:55:11,096 WARNING  D:\code\python_test\Gerber_blog\blog_env\lib\site-packages\django\core\servers\basehttp.py[line:154] "GET /api/admin/ HTTP/1.0" 404 2093
2020-08-30 20:58:03,425 WARNING  D:\code\python_test\Gerber_blog\blog_env\lib\site-packages\django\utils\log.py[line:228] Not Found: /api/article/ArtClassData
2020-08-30 20:58:03,426 WARNING  D:\code\python_test\Gerber_blog\blog_env\lib\site-packages\django\core\servers\basehttp.py[line:154] "GET /api/article/ArtClassData HTTP/1.0" 404 2135
2020-08-30 20:58:03,430 WARNING  D:\code\python_test\Gerber_blog\blog_env\lib\site-packages\django\utils\log.py[line:228] Not Found: /api/nav/navMenList
2020-08-30 20:58:03,430 WARNING  D:\code\python_test\Gerber_blog\blog_env\lib\site-packages\django\core\servers\basehttp.py[line:154] "GET /api/nav/navMenList HTTP/1.0" 404 2117
2020-08-30 20:58:03,456 WARNING  D:\code\python_test\Gerber_blog\blog_env\lib\site-packages\django\utils\log.py[line:228] Not Found: /api/outh/ThemeMy
2020-08-30 20:58:03,462 WARNING  D:\code\python_test\Gerber_blog\blog_env\lib\site-packages\django\core\servers\basehttp.py[line:154] "GET /api/outh/ThemeMy HTTP/1.0" 404 2111
2020-08-30 20:58:03,472 WARNING  D:\code\python_test\Gerber_blog\blog_env\lib\site-packages\django\utils\log.py[line:228] Not Found: /api/nav/ActiveClassAllData
2020-08-30 20:58:03,475 WARNING  D:\code\python_test\Gerber_blog\blog_env\lib\site-packages\django\utils\log.py[line:228] Not Found: /api/outh/AboutMeData
2020-08-30 20:58:03,480 WARNING  D:\code\python_test\Gerber_blog\blog_env\lib\site-packages\django\utils\log.py[line:228] Not Found: /api/article/ShowBrowseCount
2020-08-30 20:58:03,482 WARNING  D:\code\python_test\Gerber_blog\blog_env\lib\site-packages\django\core\servers\basehttp.py[line:154] "GET /api/nav/ActiveClassAllData?art_id=0&cate_id=0&article_name= HTTP/1.0" 404 2182
2020-08-30 20:58:03,486 WARNING  D:\code\python_test\Gerber_blog\blog_env\lib\site-packages\django\core\servers\basehttp.py[line:154] "GET /api/outh/AboutMeData HTTP/1.0" 404 2123
2020-08-30 20:58:03,487 WARNING  D:\code\python_test\Gerber_blog\blog_env\lib\site-packages\django\core\servers\basehttp.py[line:154] "GET /api/article/ShowBrowseCount HTTP/1.0" 404 2144
2020-08-30 20:58:03,492 WARNING  D:\code\python_test\Gerber_blog\blog_env\lib\site-packages\django\utils\log.py[line:228] Not Found: /api/outh/showLikeData
2020-08-30 20:58:03,494 WARNING  D:\code\python_test\Gerber_blog\blog_env\lib\site-packages\django\utils\log.py[line:228] Not Found: /api/article/ShowArtCommentCount
2020-08-30 20:58:03,496 WARNING  D:\code\python_test\Gerber_blog\blog_env\lib\site-packages\django\core\servers\basehttp.py[line:154] "GET /api/outh/showLikeData HTTP/1.0" 404 2126
2020-08-30 20:58:03,496 WARNING  D:\code\python_test\Gerber_blog\blog_env\lib\site-packages\django\core\servers\basehttp.py[line:154] "GET /api/article/ShowArtCommentCount HTTP/1.0" 404 2156
2020-08-30 20:58:03,538 WARNING  D:\code\python_test\Gerber_blog\blog_env\lib\site-packages\django\utils\log.py[line:228] Not Found: /api/article/ArtClassData
2020-08-30 20:58:03,539 WARNING  D:\code\python_test\Gerber_blog\blog_env\lib\site-packages\django\core\servers\basehttp.py[line:154] "GET /api/article/ArtClassData HTTP/1.0" 404 2135
2020-08-30 20:58:18,306 WARNING  D:\code\python_test\Gerber_blog\blog_env\lib\site-packages\django\utils\log.py[line:228] Not Found: /api/login/UserLogin
2020-08-30 20:58:18,307 WARNING  D:\code\python_test\Gerber_blog\blog_env\lib\site-packages\django\core\servers\basehttp.py[line:154] "GET /api/login/UserLogin?email=67@qq.com&password=123456 HTTP/1.0" 404 2156
2020-08-30 21:11:52,636 WARNING  D:\code\python_test\Gerber_blog\blog_env\lib\site-packages\django\utils\log.py[line:228] Not Found: /api/login/UserLogin
2020-08-30 21:11:52,637 WARNING  D:\code\python_test\Gerber_blog\blog_env\lib\site-packages\django\core\servers\basehttp.py[line:154] "GET /api/login/UserLogin?email=67@qq.com&password=123456 HTTP/1.0" 404 2156
2020-08-30 21:11:53,703 WARNING  D:\code\python_test\Gerber_blog\blog_env\lib\site-packages\django\utils\log.py[line:228] Not Found: /api/login/UserLogin
2020-08-30 21:11:53,703 WARNING  D:\code\python_test\Gerber_blog\blog_env\lib\site-packages\django\core\servers\basehttp.py[line:154] "GET /api/login/UserLogin?email=67@qq.com&password=123456 HTTP/1.0" 404 2156
2020-08-30 21:11:54,056 WARNING  D:\code\python_test\Gerber_blog\blog_env\lib\site-packages\django\utils\log.py[line:228] Not Found: /api/login/UserLogin
2020-08-30 21:11:54,057 WARNING  D:\code\python_test\Gerber_blog\blog_env\lib\site-packages\django\core\servers\basehttp.py[line:154] "GET /api/login/UserLogin?email=67@qq.com&password=123456 HTTP/1.0" 404 2156
2020-08-30 21:11:54,224 WARNING  D:\code\python_test\Gerber_blog\blog_env\lib\site-packages\django\utils\log.py[line:228] Not Found: /api/login/UserLogin
2020-08-30 21:11:54,224 WARNING  D:\code\python_test\Gerber_blog\blog_env\lib\site-packages\django\core\servers\basehttp.py[line:154] "GET /api/login/UserLogin?email=67@qq.com&password=123456 HTTP/1.0" 404 2156
2020-08-30 21:30:01,129 WARNING  D:\code\python_test\Gerber_blog\blog_env\lib\site-packages\django\utils\log.py[line:228] Not Found: /api/article/ArtClassData
2020-08-30 21:30:01,132 WARNING  D:\code\python_test\Gerber_blog\blog_env\lib\site-packages\django\core\servers\basehttp.py[line:154] "GET /api/article/ArtClassData HTTP/1.0" 404 2135
2020-08-30 21:30:01,138 WARNING  D:\code\python_test\Gerber_blog\blog_env\lib\site-packages\django\utils\log.py[line:228] Not Found: /api/nav/navMenList
2020-08-30 21:30:01,139 WARNING  D:\code\python_test\Gerber_blog\blog_env\lib\site-packages\django\core\servers\basehttp.py[line:154] "GET /api/nav/navMenList HTTP/1.0" 404 2117
2020-08-30 21:30:01,181 WARNING  D:\code\python_test\Gerber_blog\blog_env\lib\site-packages\django\utils\log.py[line:228] Not Found: /api/outh/ThemeMy
2020-08-30 21:30:01,182 WARNING  D:\code\python_test\Gerber_blog\blog_env\lib\site-packages\django\core\servers\basehttp.py[line:154] "GET /api/outh/ThemeMy HTTP/1.0" 404 2111
2020-08-30 21:30:01,186 WARNING  D:\code\python_test\Gerber_blog\blog_env\lib\site-packages\django\utils\log.py[line:228] Not Found: /api/outh/AboutMeData
2020-08-30 21:30:01,189 WARNING  D:\code\python_test\Gerber_blog\blog_env\lib\site-packages\django\utils\log.py[line:228] Not Found: /api/nav/ActiveClassAllData
2020-08-30 21:30:01,189 WARNING  D:\code\python_test\Gerber_blog\blog_env\lib\site-packages\django\core\servers\basehttp.py[line:154] "GET /api/outh/AboutMeData HTTP/1.0" 404 2123
2020-08-30 21:30:01,190 WARNING  D:\code\python_test\Gerber_blog\blog_env\lib\site-packages\django\core\servers\basehttp.py[line:154] "GET /api/nav/ActiveClassAllData?art_id=0&cate_id=0&article_name= HTTP/1.0" 404 2182
2020-08-30 21:30:01,199 WARNING  D:\code\python_test\Gerber_blog\blog_env\lib\site-packages\django\utils\log.py[line:228] Not Found: /api/article/ShowBrowseCount
2020-08-30 21:30:01,200 WARNING  D:\code\python_test\Gerber_blog\blog_env\lib\site-packages\django\core\servers\basehttp.py[line:154] "GET /api/article/ShowBrowseCount HTTP/1.0" 404 2144
2020-08-30 21:30:01,222 WARNING  D:\code\python_test\Gerber_blog\blog_env\lib\site-packages\django\utils\log.py[line:228] Not Found: /api/article/ArtClassData
2020-08-30 21:30:01,224 WARNING  D:\code\python_test\Gerber_blog\blog_env\lib\site-packages\django\utils\log.py[line:228] Not Found: /api/article/ShowArtCommentCount
2020-08-30 21:30:01,225 WARNING  D:\code\python_test\Gerber_blog\blog_env\lib\site-packages\django\core\servers\basehttp.py[line:154] "GET /api/article/ArtClassData HTTP/1.0" 404 2135
2020-08-30 21:30:01,225 WARNING  D:\code\python_test\Gerber_blog\blog_env\lib\site-packages\django\core\servers\basehttp.py[line:154] "GET /api/article/ShowArtCommentCount HTTP/1.0" 404 2156
2020-08-30 21:30:01,318 WARNING  D:\code\python_test\Gerber_blog\blog_env\lib\site-packages\django\utils\log.py[line:228] Not Found: /api/outh/showLikeData
2020-08-30 21:30:01,318 WARNING  D:\code\python_test\Gerber_blog\blog_env\lib\site-packages\django\core\servers\basehttp.py[line:154] "GET /api/outh/showLikeData HTTP/1.0" 404 2126
2020-08-30 21:35:12,698 ERROR    D:\code\python_test\Gerber_blog\backend\blog_interface\user_views\views.py[line:37] {"username": [{"message": "Ensure this value has at least 3 characters (it has 2).", "code": "min_length"}]}
2020-08-30 21:35:12,754 ERROR    D:\code\python_test\Gerber_blog\blog_env\lib\site-packages\django\utils\log.py[line:228] Internal Server Error: /api/user/register/
Traceback (most recent call last):
  File "D:\code\python_test\Gerber_blog\blog_env\lib\site-packages\django\core\handlers\exception.py", line 34, in inner
    response = get_response(request)
  File "D:\code\python_test\Gerber_blog\blog_env\lib\site-packages\django\core\handlers\base.py", line 115, in _get_response
    response = self.process_exception_by_middleware(e, request)
  File "D:\code\python_test\Gerber_blog\blog_env\lib\site-packages\django\core\handlers\base.py", line 113, in _get_response
    response = wrapped_callback(request, *callback_args, **callback_kwargs)
  File "D:\code\python_test\Gerber_blog\blog_env\lib\site-packages\django\views\generic\base.py", line 71, in view
    return self.dispatch(request, *args, **kwargs)
  File "D:\code\python_test\Gerber_blog\blog_env\lib\site-packages\django\views\generic\base.py", line 97, in dispatch
    return handler(request, *args, **kwargs)
  File "D:\code\python_test\Gerber_blog\backend\blog_interface\user_views\views.py", line 38, in post
    raise MyException()
blog_interface.Exception.my_exception.MyException: ²ÎÊý´íÎó
2020-08-30 21:35:12,754 ERROR    D:\code\python_test\Gerber_blog\blog_env\lib\site-packages\django\core\servers\basehttp.py[line:154] "POST /api/user/register/ HTTP/1.0" 500 80837
2020-08-30 21:36:21,020 INFO     D:\code\python_test\Gerber_blog\blog_env\lib\site-packages\django\core\servers\basehttp.py[line:154] "POST /api/user/register/ HTTP/1.0" 200 44
2020-08-30 22:11:45,287 INFO     D:\code\python_test\Gerber_blog\blog_env\lib\site-packages\django\core\servers\basehttp.py[line:154] "POST /api/user/register/ HTTP/1.0" 200 44
